[2024-08-30T23:02:38.234+0000] {local_task_job_runner.py:123} INFO - ::group::Pre task execution logs
[2024-08-30T23:02:38.262+0000] {taskinstance.py:2603} INFO - Dependencies all met for dep_context=non-requeueable deps ti=<TaskInstance: nyc_dag.prd_load manual__2024-08-30T23:02:26.938654+00:00 [queued]>
[2024-08-30T23:02:38.277+0000] {taskinstance.py:2603} INFO - Dependencies all met for dep_context=requeueable deps ti=<TaskInstance: nyc_dag.prd_load manual__2024-08-30T23:02:26.938654+00:00 [queued]>
[2024-08-30T23:02:38.278+0000] {taskinstance.py:2856} INFO - Starting attempt 1 of 0
[2024-08-30T23:02:38.304+0000] {taskinstance.py:2879} INFO - Executing <Task(PythonOperator): prd_load> on 2024-08-30 23:02:26.938654+00:00
[2024-08-30T23:02:38.317+0000] {warnings.py:112} WARNING - /home/***/.local/lib/python3.12/site-packages/***/task/task_runner/standard_task_runner.py:70: DeprecationWarning: This process (pid=2997) is multi-threaded, use of fork() may lead to deadlocks in the child.
  pid = os.fork()

[2024-08-30T23:02:38.319+0000] {standard_task_runner.py:72} INFO - Started process 2999 to run task
[2024-08-30T23:02:38.319+0000] {standard_task_runner.py:104} INFO - Running: ['***', 'tasks', 'run', 'nyc_dag', 'prd_load', 'manual__2024-08-30T23:02:26.938654+00:00', '--job-id', '239', '--raw', '--subdir', 'DAGS_FOLDER/nyc_dag_script.py', '--cfg-path', '/tmp/tmp6jmomv36']
[2024-08-30T23:02:38.323+0000] {standard_task_runner.py:105} INFO - Job 239: Subtask prd_load
[2024-08-30T23:02:38.412+0000] {task_command.py:467} INFO - Running <TaskInstance: nyc_dag.prd_load manual__2024-08-30T23:02:26.938654+00:00 [running]> on host 107c7aa6860c
[2024-08-30T23:02:38.574+0000] {taskinstance.py:3122} INFO - Exporting env vars: AIRFLOW_CTX_DAG_EMAIL='tolutosin16@gmail.org' AIRFLOW_CTX_DAG_OWNER='tolu_samuel' AIRFLOW_CTX_DAG_ID='nyc_dag' AIRFLOW_CTX_TASK_ID='prd_load' AIRFLOW_CTX_EXECUTION_DATE='2024-08-30T23:02:26.938654+00:00' AIRFLOW_CTX_TRY_NUMBER='1' AIRFLOW_CTX_DAG_RUN_ID='manual__2024-08-30T23:02:26.938654+00:00'
[2024-08-30T23:02:38.581+0000] {taskinstance.py:731} INFO - ::endgroup::
[2024-08-30T23:02:38.692+0000] {connection.py:414} INFO - Snowflake Connector for Python Version: 3.12.0, Python Version: 3.12.5, Platform: Linux-5.15.153.1-microsoft-standard-WSL2-x86_64-with-glibc2.36
[2024-08-30T23:02:38.699+0000] {connection.py:1187} INFO - Connecting to GLOBAL Snowflake domain
[2024-08-30T23:02:38.702+0000] {connection.py:1268} INFO - This connection is in OCSP Fail Open Mode. TLS Certificates would be checked for validity and revocation status. Any other Certificate Revocation related exceptions or OCSP Responder failures would be disregarded in favor of connectivity.
[2024-08-30T23:02:39.596+0000] {logging_mixin.py:190} INFO - An error occurred during loading to production: (snowflake.connector.errors.DatabaseError) 250001 (08001): None: Failed to connect to DB: @mteopxr-yu26234.snowflakecomputing.com:443. Incorrect username or password was specified.
(Background on this error at: https://sqlalche.me/e/14/4xp6)
[2024-08-30T23:02:39.597+0000] {python.py:240} INFO - Done. Returned value was: None
[2024-08-30T23:02:39.671+0000] {taskinstance.py:340} INFO - ::group::Post task execution logs
[2024-08-30T23:02:39.672+0000] {taskinstance.py:352} INFO - Marking task as SUCCESS. dag_id=nyc_dag, task_id=prd_load, run_id=manual__2024-08-30T23:02:26.938654+00:00, execution_date=20240830T230226, start_date=20240830T230238, end_date=20240830T230239
[2024-08-30T23:02:39.785+0000] {local_task_job_runner.py:261} INFO - Task exited with return code 0
[2024-08-30T23:02:39.819+0000] {taskinstance.py:3891} INFO - 0 downstream tasks scheduled from follow-on schedule check
[2024-08-30T23:02:39.824+0000] {local_task_job_runner.py:240} INFO - ::endgroup::
